<?xml version="1.0"?>
<robot xmlns:xacro="http://wiki.ros.org/xacro" name="$(arg robotNamespace)">
    <!-- Arguments -->
    <xacro:arg name="default_mia_model" default="false" />
    <xacro:arg name="right_hand" default="true" />
    <xacro:arg name="joint_limits_config_filename" default="joint_limits.yaml" />
    <xacro:arg name="hw_interface_thumb_fle" default="VelocityJointInterface"/>
    <xacro:arg name="hw_interface_index_fle" default="VelocityJointInterface"/>
    <xacro:arg name="hw_interface_mrl_fle" default="VelocityJointInterface"/>
    <xacro:arg name="robotNamespace" default="mia_hand_camera"/> <!-- /mia_hand_camera -->
    <xacro:arg name="camera_name" default="camera" />
    <xacro:arg name="camera_topic_ns" default="camera" />
    <xacro:arg name="wrist_rotation" default="true" />



    <!-- Materials -->
    <xacro:include filename="$(find mia_hand_description)/materials/materials.xacro"/>

    <!-- Import Transmission and all Gazebo-customization elements, including Gazebo colors and teh Gazebo plugin-->
    <xacro:include filename="$(find mia_hand_description)/urdf/mia_hand_gazebo.urdf.xacro" />

    <xacro:mia_gazebo hw_interface_thumb_fle="$(arg hw_interface_thumb_fle)"
                        hw_interface_index_fle="$(arg hw_interface_index_fle)"
                        hw_interface_mrl_fle= "$(arg hw_interface_mrl_fle)"
                        robotNamespace= "$(arg robotNamespace)"
                        LoadGZPlugin="true"/>

    <!-- Import default robot model -->
    <xacro:if value="$(arg right_hand)">
        <xacro:include filename="$(find mia_hand_description)/urdf/mia_hand.urdf.xacro"/>
    </xacro:if>

    <xacro:unless value="$(arg right_hand)">
        <xacro:include filename="$(find mia_hand_description)/urdf/mia_hand_left.urdf.xacro"/>
    </xacro:unless>

    <xacro:if value="$(arg default_mia_model)">
        <xacro:if value="$(arg right_hand)">
        <xacro:mia_hand_robot />
        </xacro:if>
        <xacro:unless value="$(arg right_hand)">
        <xacro:mia_hand_robot_left />
        </xacro:unless>
    </xacro:if>

    <xacro:unless value="$(arg default_mia_model)">
        <xacro:if value="$(arg right_hand)">
        <xacro:mia_hand_robot joint_limits_parameters_file= '$(find mia_hand_description)/calibration/$(arg joint_limits_config_filename)' />
        </xacro:if>

        <xacro:unless value="$(arg right_hand)">
            <xacro:mia_hand_robot_left joint_limits_parameters_file= '$(find mia_hand_description)/calibration/$(arg joint_limits_config_filename)' />
        </xacro:unless>
    </xacro:unless>

    <!--world to palm transform-->
    <!-- world and world interface. Makes it convenient to move the whole environment according to the world origin -->
    <!-- <link name="world" />
    <link name="world_interface"/> -->

    <!-- world<->world_interface joint -->
    <!-- <joint name="world_interface_to_world" type="fixed">
        <parent link="world" />
        <child link="world_interface" />
    </joint> -->

    <!--joint between world_interface and mia hand-->
    <!-- <xacro:if value="$(arg right_hand)">
        <joint name="j_palm" type="fixed">
        <origin xyz="0 0 0.2" rpy="0 3.1416 0"/> 
        <parent link="world_interface"/>
        <child link="palm"/>
        </joint>
    </xacro:if>
    <xacro:unless value="$(arg right_hand)">
        <joint name="j_palm_interface" type="fixed">
        <origin xyz="0 0 0.2" rpy="3.1416 0 0"/>
        <parent link="world_interface"/>
        <child link="palm"/>
        </joint>
    </xacro:unless>  -->

    <!-- base_link to palm transform-->
    <link name="base_link"/>

    <xacro:if value="$(arg wrist_rotation)">
        <link name="forearm_link"/>
        <!-- Motions for a right hand: -->
        <!-- Pronation (inwards so the palm is down) /suppination (palm up) = Rotation -->
        <joint name="j_wrist_rotation" type="revolute">
            <origin xyz="0 0 0" rpy="0 0 0"/>
            <parent link="forearm_link"/>
            <child link="rot_to_exfle_link"/>
        </joint>
        <link name="rot_to_exfle_link" />

        <!-- Extension (up) / flexion (down) = up/down  -->
        <joint name="j_wrist_exfle" type="revolute">
            <origin xyz="0 0 0" rpy="0 0 0"/>
            <parent link="rot_to_exfle_link"/>
            <child link="exfle_to_ulra_link"/>
        </joint>
        <link name="exfle_to_ulra_link" />
        
        <!-- Ulnar (outwards) / Radial (inwards)-->
        <joint name="j_wrist_ulra" type="revolute">
            <origin xyz="0 0 0" rpy="0 0 0"/>
            <parent link="exfle_to_ulra_link"/>
            <child link="wrist_link"/>
        </joint>
        
        <link name="wrist_link" />
        
    </xacro:if>
    <xacro:unless value="$(arg wrist_rotation)">
        <link name="wrist_link" />

    </xacro:unless>
    

    <xacro:if value="$(arg right_hand)">
        <joint name="j_palm" type="fixed">
        <origin xyz="0 0 0" rpy="0 0 0"/> <!-- origin xyz="0 0 1" rpy="1.57 0 0""/ -->
        <parent link="wrist_link"/>
        <child link="palm"/>
        </joint>
    </xacro:if>
    <xacro:unless value="$(arg right_hand)">
        <joint name="j_palm" type="fixed">
        <origin xyz="0 0 0" rpy="0 0 0"/> <!-- origin xyz="0 0 1" rpy="1.57 3.14 0""/ -->
        <parent link="wrist_link"/>
        <child link="palm"/>
        </joint> 
    </xacro:unless>

    <!-- realsense camera -->
    <xacro:include filename="$(find realsense2_description)/urdf/_d435.urdf.xacro"/>
    <xacro:if value="$(arg right_hand)">
        <xacro:sensor_d435 parent="palm" name="$(arg camera_name)" use_nominal_extrinsics="true">
            <origin xyz="0 0 -0.05" rpy="3.1416 0 1.5708"/>
        </xacro:sensor_d435>
    </xacro:if>
    <xacro:unless value="$(arg right_hand)">
        <xacro:sensor_d435 parent="palm" name="$(arg camera_name)" use_nominal_extrinsics="true">
            <origin xyz="0 0 -0.05" rpy="0 3.1416 1.5708"/>
        </xacro:sensor_d435>
    </xacro:unless>
    
    <!-- realsense Gazebo Plugin -->
    <xacro:include filename="$(find sim_world)/urdf/cameras/_d435.gazebo.xacro"/>
    <xacro:gazebo_d435 camera_name="$(arg camera_name)" 
                    reference_link="$(arg camera_name)_link" 
                    topics_ns="$(arg camera_topic_ns)"
                    depth_optical_frame="$(arg camera_name)_depth_optical_frame" 
                    color_optical_frame="$(arg camera_name)_color_optical_frame" 
                    infrared1_optical_frame="$(arg camera_name)_left_ir_optical_frame" 
                    infrared2_optical_frame="$(arg camera_name)_right_ir_optical_frame" />

</robot>
